Workbook

Sheet Dashboard
A1: AARON'S TRADING DASHBOARD
A2: 20-Day Experiment: A+ Long Only — Strong Trend Conditions
A4: 20-DAY EXPERIMENT
A5: Days Completed | B5: =COUNTIFS('Trade Log'!D:D,"Experiment Day*") | C5: / 20 | D5: HISTORICAL (April Pre-Experiment)
A6: Total Trades | B6: =COUNTIF('Trade Log'!D:D,"Experiment Day*") | D6: Total Trades | E6: =COUNTIF('Trade Log'!D:D,"Historical")
A7: Winners (>$5) | B7: =COUNTIFS('Trade Log'!D:D,"Experiment Day*",'Trade Log'!S:S,">5") | D7: Win Rate | E7: =IFERROR(COUNTIFS('Trade Log'!D:D,"Historical",'Trade Log'!S:S,">5")/(COUNTIFS('Trade Log'!D:D,"Historical",'Trade Log'!S:S,">5")+COUNTIFS('Trade Log'!D:D,"Historical",'Trade Log'!S:S,"<-5")),0)
A8: Losers (<-$5) | B8: =COUNTIFS('Trade Log'!D:D,"Experiment Day*",'Trade Log'!S:S,"<-5") | D8: Total Net P/L | E8: =SUMIFS('Trade Log'!S:S,'Trade Log'!D:D,"Historical")
A9: Win Rate | B9: =IFERROR(B7/(B7+B8),0) | D9: Avg Win | E9: =IFERROR(AVERAGEIFS('Trade Log'!S:S,'Trade Log'!D:D,"Historical",'Trade Log'!S:S,">5"),0)
A10: Total Net P/L | B10: =SUMIFS('Trade Log'!S:S,'Trade Log'!D:D,"Experiment Day*") | D10: Avg Loss | E10: =IFERROR(AVERAGEIFS('Trade Log'!S:S,'Trade Log'!D:D,"Historical",'Trade Log'!S:S,"<-5"),0)
A11: Avg Win | B11: =IFERROR(AVERAGEIFS('Trade Log'!S:S,'Trade Log'!D:D,"Experiment Day*",'Trade Log'!S:S,">5"),0) | D11: Best Trade | E11: =SUMPRODUCT(MAX(('Trade Log'!D2:D100="Historical")*'Trade Log'!S2:S100))
A12: Avg Loss | B12: =IFERROR(AVERAGEIFS('Trade Log'!S:S,'Trade Log'!D:D,"Experiment Day*",'Trade Log'!S:S,"<-5"),0) | D12: Worst Trade | E12: =-SUMPRODUCT(MAX(('Trade Log'!D2:D100="Historical")*-'Trade Log'!S2:S100*('Trade Log'!S2:S100<>"")))
A13: Avg R-Multiple | B13: =IFERROR(AVERAGEIFS('Trade Log'!U:U,'Trade Log'!D:D,"Experiment Day*"),0) | D13: Profit Factor | E13: =IFERROR(SUMIFS('Trade Log'!S:S,'Trade Log'!D:D,"Historical",'Trade Log'!S:S,">5")/ABS(SUMIFS('Trade Log'!S:S,'Trade Log'!D:D,"Historical",'Trade Log'!S:S,"<-5")),0)
A14: Profit Factor | B14: =IFERROR(SUMIFS('Trade Log'!S:S,'Trade Log'!D:D,"Experiment Day*",'Trade Log'!S:S,">5")/ABS(SUMIFS('Trade Log'!S:S,'Trade Log'!D:D,"Experiment Day*",'Trade Log'!S:S,"<-5")),0)
A16: BY DIRECTION (HISTORICAL)
A17: Direction | B17: Trades | C17: Win Rate | D17: Total P/L | E17: Avg Trade | F17: Note
A18: Bullish | B18: =COUNTIFS('Trade Log'!D:D,"Historical",'Trade Log'!H:H,"Bullish") | C18: =IFERROR(COUNTIFS('Trade Log'!D:D,"Historical",'Trade Log'!H:H,"Bullish",'Trade Log'!S:S,">5")/(COUNTIFS('Trade Log'!D:D,"Historical",'Trade Log'!H:H,"Bullish",'Trade Log'!S:S,">5")+COUNTIFS('Trade Log'!D:D,"Historical",'Trade Log'!H:H,"Bullish",'Trade Log'!S:S,"<-5")),0) | D18: =SUMIFS('Trade Log'!S:S,'Trade Log'!D:D,"Historical",'Trade Log'!H:H,"Bullish") | E18: =IFERROR(D18/B18,0) | F18: YOUR EDGE
A19: Bearish | B19: =COUNTIFS('Trade Log'!D:D,"Historical",'Trade Log'!H:H,"Bearish") | C19: =IFERROR(COUNTIFS('Trade Log'!D:D,"Historical",'Trade Log'!H:H,"Bearish",'Trade Log'!S:S,">5")/(COUNTIFS('Trade Log'!D:D,"Historical",'Trade Log'!H:H,"Bearish",'Trade Log'!S:S,">5")+COUNTIFS('Trade Log'!D:D,"Historical",'Trade Log'!H:H,"Bearish",'Trade Log'!S:S,"<-5")),0) | D19: =SUMIFS('Trade Log'!S:S,'Trade Log'!D:D,"Historical",'Trade Log'!H:H,"Bearish") | E19: =IFERROR(D19/B19,0) | F19: YOUR LEAK
A21: BREAKTHROUGH METRICS
A22: Best Historical Win | B22: =E11 | C22: Best Experiment Win | D22: =SUMPRODUCT(MAX((LEFT('Trade Log'!D2:D100,10)="Experiment")*'Trade Log'!S2:S100)) | E22: Improvement | F22: =D22-B22
A23: Hist. Avg Win | B23: =E9 | C23: Exp. Avg Win | D23: =B11 | E23: Improvement | F23: =D23-B23

Sheet Trade Log
A1: Date | B1: Day | C1: Trade # | D1: Phase | E1: Symbol | F1: Strike/Type | G1: Expiry | H1: Direction | I1: Entry Time | J1: Exit Time | K1: Time in Trade (min) | L1: Entry Premium | M1: Exit Premium | N1: Final Stop | O1: Initial Stop | P1: Qty | Q1: Gross P/L | R1: Commission | S1: Net P/L | T1: Risk ($) | U1: R-Multiple | V1: Setup Type | W1: Market Condition | X1: Grade | Y1: Rules Followed | Z1: Forced | AA1: Mental State (1-10) | AB1: Notes | AC1: Exit Method
A2: 2026-04-01 | B2: Tue | C2: 1 | D2: Historical | E2: QQQ | F2: 582C | G2: 04/01/26 | H2: Bullish | I2: 07:50:23 | J2: 07:54:06 | K2: 4 | L2: 1.85 | M2: 2.22 | P2: 1 | Q2: 37 | R2: 1.6 | S2: 35.4
A3: 2026-04-01 | B3: Tue | C3: 2 | D3: Historical | E3: QQQ | F3: 583C | G3: 04/01/26 | H3: Bullish | I3: 08:38:04 | J3: 08:39:19 | K3: 1 | L3: 1.92 | M3: 2.35 | P3: 1 | Q3: 43 | R3: 1.6 | S3: 41.4
A4: 2026-04-02 | B4: Wed | C4: 1 | D4: Historical | E4: QQQ | F4: 579C | G4: 04/02/26 | H4: Bullish | I4: 08:28:12 | J4: 08:30:02 | K4: 2 | L4: 1.96 | M4: 1.79 | P4: 1 | Q4: -17 | R4: 1.6 | S4: -18.6
A5: 2026-04-02 | B5: Wed | C5: 2 | D5: Historical | E5: QQQ | F5: 579C | G5: 04/02/26 | H5: Bullish | I5: 08:31:05 | J5: 08:32:22 | K5: 1 | L5: 2.17 | M5: 1.93 | P5: 1 | Q5: -24 | R5: 1.6 | S5: -25.6
A6: 2026-04-02 | B6: Wed | C6: 3 | D6: Historical | E6: QQQ | F6: 583P | G6: 04/02/26 | H6: Bearish | I6: 09:00:36 | J6: 09:03:34 | K6: 3 | L6: 2.55 | M6: 2.35 | P6: 1 | Q6: -20 | R6: 1.6 | S6: -21.6
A7: 2026-04-06 | B7: Sun | C7: 1 | D7: Historical | E7: QQQ | F7: 587C | G7: 04/06/26 | H7: Bullish | I7: 07:41:48 | J7: 07:44:40 | K7: 3 | L7: 2.5 | M7: 2.55 | P7: 1 | Q7: 5 | R7: 1.6 | S7: 3.4
A8: 2026-04-06 | B8: Sun | C8: 2 | D8: Historical | E8: QQQ | F8: 589C | G8: 04/06/26 | H8: Bullish | I8: 08:28:14 | J8: 08:32:28 | K8: 4 | L8: 1.53 | M8: 1.36 | P8: 1 | Q8: -17 | R8: 1.6 | S8: -18.6
A9: 2026-04-06 | B9: Sun | C9: 3 | D9: Historical | E9: QQQ | F9: 587P | G9: 04/06/26 | H9: Bearish | I9: 08:55:28 | J9: 08:56:15 | K9: 1 | L9: 1.81 | M9: 1.54 | P9: 1 | Q9: -27 | R9: 1.6 | S9: -28.6
A10: 2026-04-07 | B10: Mon | C10: 1 | D10: Historical | E10: QQQ | F10: 580P | G10: 04/07/26 | H10: Bearish | I10: 08:12:53 | J10: 08:15:57 | K10: 3 | L10: 2.02 | M10: 1.69 | P10: 1 | Q10: -33 | R10: 1.6 | S10: -34.6
A11: 2026-04-07 | B11: Mon | C11: 2 | D11: Historical | E11: QQQ | F11: 581P | G11: 04/07/26 | H11: Bearish | I11: 08:18:09 | J11: 08:20:21 | K11: 2 | L11: 2.24 | M11: 1.84 | P11: 1 | Q11: -40 | R11: 1.6 | S11: -41.6
A12: 2026-04-07 | B12: Mon | C12: 3 | D12: Historical | E12: QQQ | F12: 582P | G12: 04/07/26 | H12: Bearish | I12: 08:28:09 | J12: 08:44:12 | K12: 16 | L12: 2.25 | M12: 2.25 | P12: 1 | Q12: 0 | R12: 1.6 | S12: -1.6
A13: 2026-04-07 | B13: Mon | C13: 4 | D13: Historical | E13: QQQ | F13: 580P | G13: 04/07/26 | H13: Bearish | I13: 08:59:17 | J13: 09:02:10 | K13: 3 | L13: 1.87 | M13: 1.89 | P13: 1 | Q13: 2 | R13: 1.6 | S13: 0.4
... A46: 2026-04-23 | B46: Wed | C46: 2 | D46: Historical | E46: QQQ | F46: 653P | G46: 04/23/26 | H46: Bearish | I46: 08:05:09 | J46: 08:15:07 | K46: 10 | L46: 1.58 | M46: 1.58 | P46: 1 | Q46: 0 | R46: 1.6 | S46: -1.6
A47: 2026-04-27 | B47: Mon | C47: 1 | D47: Experiment Day 1 | E47: QQQ | F47: 663C | G47: 04/27/26 | H47: Bullish | I47: 08:12:04 | J47: 08:24:05 | K47: 12 | L47: 1.32 | M47: 1.04 | N47: 1.02 | O47: 1.02 | P47: 1 | Q47: -28 | R47: 1.6 | S47: -29.6 | T47: 30 | U47: -0.99 | V47: Pullback long after morning flush | W47: Strong->Chop | X47: B+ | Y47: Y | Z47: N | AA47: 8 | AB47: Setup invalidated as 5-min stoch crossed down. Held stop per plan. After stop, applied cool-down rule. Watched 660.50->663.70 bounce without entering. Skipped multiple B+ setups during chop. Closed platform without forcing trade #2. | AC47: Stop Hit
A48: 2026-04-28 | B48: Tue | C48: 1 | D48: Experiment Day 2 | E48: QQQ | F48: 657C | G48: 04/28/26 | H48: Bullish | I48: 07:56:58 | J48: 08:06:09 | K48: 9 | L48: 2.11 | M48: 2.89 | N48: 1.91 | O48: 1.81 | P48: 1 | Q48: 78 | R48: 1.6 | S48: 76.4 | T48: 20 | U48: 3.82 | V48: Pullback long at support box (657.01-657.51) | W48: Strong (gap-down recovery) | X48: A | Y48: Y | Z48: N | AA48: 9 | AB48: Pre-market analysis identified gap-down recovery setup. Waited through 15-min rule. Watched first bounce without chasing. Identified 657.01-657.51 pullback box. Entered $2.11 on curl from oversold (textbook). Initial stop $1.91 ($20 risk). HELD past historical exit zone — let winner run. Exited $2.89 = +$76.40 = 3.82R. Best single trade ever recorded. | AC48: Manual at Structure
A49: 2026-04-29 | B49: Wed | C49: 0 | D49: Experiment Day 3 | E49: — | F49: NO LIVE TRADES | G49: — | H49: N/A | I49: — | J49: — | K49: 0 | O49: — | P49: 0 | Q49: 0 | R49: 0 | S49: 0 | T49: 0 | U49: 0 | V49: DISCIPLINE DAY — Fed Day SIM only | W49: Fed FOMC announcement | X49: A+ | Y49: Y | Z49: N | AA49: 9 | AB49: FED DAY (FOMC + Powell press conf at 12:00/12:30 MT). Made decision pre-open to SIM-only on Fed day. Took 1 SIM trade in morning (+$31 SIM, validated A+ setup still fires in pre-Fed regime). Did NOT go live despite winning SIM. Held discipline through the entire pre-Fed session. KEY LESSON: Discipline of skipping live trading when regime is unfavorable counts as much as taking winning trades. | AC49: N/A (No Trade)
A50: 2026-04-30 | B50: Thu | C50: 1 | D50: Experiment Day 4 | E50: QQQ | F50: Long Call | G50: 04/30/26 | H50: Bullish | I50: 07:46 | J50: 08:00 | K50: 14 | L50: 2.69 | M50: 2.37 | N50: 2.39 | O50: 2.39 | P50: 1 | Q50: -32 | R50: 1.6 | S50: -33.6 | T50: 30 | U50: -1.12 | V50: Pullback long at red 200 MA support after 666 rejection | W50: Failed bounce / corrective regime | X50: A- | Y50: Y | Z50: N | AA50: 7 | AB50: Setup criteria met (1-min curl from oversold at 661 red 200 MA support after Fed-day gap-up rejection from 666). However regime had shifted to corrective. Bullish thesis failed quickly - 1-min stoch hit 100 fast indicating momentum exhaustion right after entry. Stop honored cleanly. Did NOT take second live trade despite cool-down clearing. Recognized regime mismatch and stood down. KEY: Initiated bearish paper-trade research after observing A+ bear setup form at 8:07 MT during cool-down. Day 4 turned into regime-shift learning day rather than make-back attempt. | AC50: Stop Hit
A51: 46143 | B51: Fri | C51: 6 | D51: Experiment Day 5 | E51: QQQ | F51: 673C | G51: 46143 | H51: Long | I51: 46143.359 | J51: 46143.371 | K51: 16.58 | L51: 1.35 | M51: 1.97 | N51: 1.8 | O51: 1.05 | P51: 1 | Q51: 62 | R51: 1.6 | S51: 60.4 | T51: 30 | U51: 2.01 | V51: A+ Bullish Pullback | W51: Bullish post-ISM, multi-tf stoch reset | X51: A | Y51: Yes | Z51: No | AA51: 9 | AB51: Broke $43 historical win ceiling. Entered on curl not cross. 4 rejections at 674, exited at structural level before 5th test. Held through give-back +53 to +23 to +61. Stop hardcoded 30c on entry, manually trailed BE -> +45 -> +50 -> +15 lock as structure evolved. Final exit manual at 1.97. Disciplined exit at end-of-nerve. No rule violations. | AC51: Manual at Structure
A52: 46146 | B52: Mon | C52: 0 | D52: Experiment Day 6 | E52: — | F52: NO LIVE TRADES | G52: — | H52: N/A | I52: — | J52: — | K52: 0 | O52: — | P52: 0 | Q52: 0 | R52: 0 | S52: 0 | T52: 0 | U52: 0 | V52: Discipline Day | W52: Range chop 674-676 | X52: A+ (No Trade) | Y52: Yes | Z52: No | AA52: 7 | AB52: Range-bound chop. 4 rejections at 676, failed breakout 8:53. No A+ pullback to real support (5-min 21 EMA at 674.75 never tested post-open). Closed platform 9:08 MT. Mid-day flushed to 669 confirming regime instability post-close. | AC52: N/A (No Trade)
A53: 46147 | B53: Tue | C53: 0 | D53: Experiment Day 7 | E53: — | F53: NO LIVE TRADES | G53: — | H53: N/A | I53: — | J53: — | K53: 0 | O53: — | P53: 0 | Q53: 0 | R53: 0 | S53: 0 | T53: 0 | U53: 0 | V53: Discipline Day | W53: Gap-up post-ISM, B+ setups only | X53: A+ (No Trade) | Y53: Yes | Z53: No | AA53: 8 | AB53: ISM Services 53.6 / JOLTs 6.866M / New Home Sales beat = mildly dovish. Print spike 678->684, reversal to 679. Three B+ setups skipped (1-min curls without 5-min participation). One ran ~1.7pts (would have been ~$50-70). A+ requires multi-tf alignment AND price at REAL support. | AC53: N/A (No Trade)
A54: 46148 | B54: Wed | C54: 7 | D54: Experiment Day 8 | E54: AAPL | F54: 285C | G54: 46150 | H54: Long | I54: 46148.372 | J54: 46148.381 | K54: 13 | L54: 2.4 | M54: 2.1 | N54: 2.1 | O54: 2.1 | P54: 1 | Q54: -30 | R54: 1.6 | S54: -31.6 | T54: 30 | U54: -1.05 | V54: A+ Bullish Pullback | W54: Bullish gap-up, 15-min stoch reset finally on higher tf | X54: A (process) | Y54: Yes (process) | Z54: No | AA54: 8 | AB54: First non-QQQ trade - TICKER DEVIATION FLAGGED. AAPL 260508C285 (T+2, not 0DTE - EXPIRY DEVIATION FLAGGED). Hardcoded SBA stop placed 5 sec after entry - best stop discipline of experiment. Setup invalidated quickly, stop hit precisely at 30c. No widening, no averaging, no hesitation. Process A across the board. QQQ-only and 0DTE-only LOCKED IN for Days 9-20. Earlier 8:03 QQQ setup had 5-min stoch at 89 (elevated) - coach applied stricter reset interpretation; setup met written criteria. Skipped, ran ~$2 underlying. Definitional ambiguity flagged for Day 20 review. | AC54: Stop Hit
A55: 46149 | B55: Thu | C55: 8 | D55: Experiment Day 9 | E55: QQQ | F55: 696C (1DTE - ACCIDENTAL) | G55: 46150 | H55: Long | I55: 46149.325 | J55: 46149.344 | K55: 27.7 | L55: 3.76 | M55: 5.43 | N55: 4.76 | O55: 3.46 | P55: 1 | Q55: 167 | R55: 1.6 | S55: 165.4 | T55: 30 | U55: 5.51 | V55: A+ Bullish Pullback (multi-tf alignment) | W55: Strong trend, clean structure | X55: A+ | Y55: Yes (CONTRACT EXPIRY VIOLATION - accidental 1DTE instead of 0DTE) | Z55: No | AA55: 9 | AB55: BEST DISCIPLINED TRADE OF EXPERIMENT. Multi-tf alignment achieved at 695.93 (1-min curl + 2-min reset + 5-min fast at floor). Hardcoded SBA stop placed 12 sec after entry. Trailed structurally: BE -> +25 -> +40 -> +60 -> +80 -> +100 lock. Held through give-backs. Did NOT exit at $60 (Day 5 ceiling), did NOT exit at $137 (peak). Manual market exit at 5.43 on structural rejection of 699. ACCIDENTAL CONTRACT DEVIATION: 1DTE instead of 0DTE - higher delta contributed to dollar outcome. Estimated comparable 0DTE: +$80-130 net. WORKFLOW FIX: pre-trade verification protocol added. | AC55: Manual at Structure
A56: 46150 | B56: Fri | C56: 9 | D56: Experiment Day 10 | E56: QQQ | F56: 705C | G56: 46150 | H56: Long | I56: 46150.36 | J56: 46150.382 | K56: 32 | L56: 1.86 | M56: 2.77 | N56: 2.81 | O56: 1.56 | P56: 1 | Q56: 91 | R56: 1.6 | S56: 89.4 | T56: 30 | U56: 2.98 | V56: A+ Bullish Pullback | W56: Strong trend post-NFP beat | X56: A | Y56: Yes | Z56: No | AA56: 9 | AB56: Day 10 - First trade using new Structural Trail Stop methodology. NFP April 115K vs 62K consensus = strong beat, gap up from ~694 to 706+. Waited 1+ hour for real setup vs chasing pre-market spike. Multi-tf alignment achieved at 5-min EMA zone (~704-705). 1-min curl entry. Hardcoded 30c initial stop, manually trailed structurally. Held through every historical psychological exit point ($43, $57, $73, $102). Stop caught structural breakdown of 5-min stoch with slippage (filled $2.77 vs stop level $2.81 = 4c slippage = acceptable cost of SBA market stops). Exit method = Stop Hit (NOT manual at nerve - first clean execution of new methodology). | AC56: Stop Hit
A57: 46153 | B57: Mon | C57: 0 | D57: Experiment Day 11 | E57: — | F57: NO LIVE TRADES | G57: — | H57: N/A | I57: — | J57: — | K57: 0 | P57: 0 | Q57: 0 | R57: 0 | S57: 0 | T57: 0 | U57: 0 | V57: Discipline Day | W57: V-recovery into 712.50 supply; post-NFP digestion, pre-CPI | X57: A+ (No Trade) | Y57: Yes | Z57: No | AA57: 7 | AB57: Pre-CPI digestion day. 15-min trend up intact but tested (deepest pullback of the move held 15-min 50 EMA at 709.78). Two A+ candidates: (1) 7:42 MT bullish curl at MA cluster ~711 — disqualified by 7:30-7:45 no-trade window (correctly skipped). (2) 8:32 MT bullish curl off 15-min 50 EMA at 709.78 after deep flush — full multi-tf alignment (1-min yellow 15 crossed white 12 at floor, 2-min crossed up from support, 15-min stoch reset to 9.36, price at macro support). Skipped on real-time read citing 5-min yellow at 0 not yet "climbing." Move ran 709.78 → 713.34 (+$3.56 underlying / est +$120-180 on 0DTE). COACHING DEBRIEF: over-strict interpretation of 5-min "climbing." When 15-min stoch is in fresh deep reset and price at meaningful macro support, 5-min "climbing" criterion is satisfied by POSITION (yellow in support zone, ready to turn) — bar-over-bar rise lags the 1-min curl by definition. Same definitional issue as Day 8 8:03 setup. Refined interpretation logged for Days 12-20. Rejected 3 B-grade bounce attempts (7:50, 7:58, 8:01) in 711-712 chop range — all correctly skipped. Did not chase 712.69 V-recovery into known 712.50 supply with overbought stochs. Stopped 9:11 MT. | AC57: N/A No Trade
A58: 46154 | B58: Tue | C58: 0 | D58: Experiment Day 12 | E58: — | F58: NO LIVE TRADES | G58: — | H58: N/A | I58: — | J58: — | K58: 0 | P58: 0 | Q58: 0 | R58: 0 | S58: 0 | T58: 0 | U58: 0 | V58: Hot CPI day — no A+ live setup | W58: Hot CPI (Core MoM 0.4% vs 0.3% cons, Core YoY 2.8% vs 2.7%, Headline YoY 3.8% vs 3.7%); 15-min damaged/regime in question | X58: A+ (No Trade) | Y58: Yes | Z58: No | AA58: 8 | AB58: Hot CPI flush pre-market 712.79 → 706.82 (-0.91%). 15-min macro damaged — lower low confirmed, MAs flattening, Strong Trend Up tested. Per experiment rules (A+ longs require Strong Trend Up, broken) no live A+ available. ALSO Day 12 = experiment policy decision day: switched to SIM bear practice. Two SIM trades: (1) SIM-1 entered put 8:14 MT on 1-min "first hint of curl" while white still climbing, adverse to 708.31, exited at structure for ~-$8 SIM. Lesson: 1-min is head-fake prone in volatile bear regime — 2-min curl is the cleaner trigger. (2) SIM-2 entered 8:56 MT on confirmed 2-min curl at resistance after bounce, ~705 area. Held through -$63 drawdown (from +$125 to +$62) without panic-exit. Trailed structural stops: 704.55 → 703.70 → 703.55 → 702.60. 15-min red 200 EMA broke during move. Closed +$217 SIM when had to leave for work. SIM session net +$208. KEY INSIGHT: bear breakthrough on historically-losing direction using own articulated 2-min curl methodology + structural trail. SIM is research, separate from live experiment count. | AC58: N/A No Trade
A59: 46155 | B59: Wed | C59: 1 | D59: Experiment Day 13 | E59: QQQ | F59: 709C | G59: 46155 | H59: Long | I59: 0.3618287 | J59: 0.36508102 | K59: 4.7 | L59: 2.01 | M59: 2.03 | N59: 2.01 | O59: 1.71 | P59: 1 | Q59: 2 | R59: 1.6 | S59: 0.4 | T59: 30 | U59: 0.07 | V59: A+ Bullish Pullback (late entry on breakout retest) | W59: Hot PPI day — regime in question; bounce-retest of 708.50 breakout | X59: A- (late entry; ~$1 late from optimal 707.50-708 zone) | Y59: Yes (entry/stop); No (BE move premature per Structural Trail methodology) | Z59: No | AA59: 7 | AB59: Day 13 Trade 1. Live shorts added to experiment Day 13 (separate rule update); this trade was long. Hot PPI 6:30 MT: MoM 1.4% vs 0.5% cons, Core MoM 1.0% vs 0.3%, Core YoY 5.2% vs 4.3%. Pre-open flush 712.79 → 706.32 then bounce attempt. Morning A+ at 707.50-708 zone MISSED — coach framed multi-tf slingshot at held macro support (706.32) as "falling knife / continuation, not setup" at 7:46 and 7:49 when chart showed Scenario A bullish slingshot. By 7:53 setup identified but framed as "your call" rather than execute call. Move ran 707.50 → 710.70 (+$3+, est +$100-130 on 0DTE). COACHING ERROR #1 FLAGGED. Trade actually taken: late entry 708.91 on 1-min curl pullback to breakout retest after price already at 708.50 area. Peaked +$17 at 709.27. COACHING ERROR #2: coach instructed BE move at +$17 on normal 30-cent pullback instead of structural trail at 708.45. Per Day 10 methodology, BE move premature — structure had not broken. BE stop caught the normal pullback to retest 9 EMA. Trade exited at $2.03 ($0.02 above entry) = +$0.40 net after commission. Subsequent move ran from ~708.80 → 710.70 (would have captured +$70-90 more with structural trail at 708.45). Exit Method classified as Manual at Structure (BE), but flagged in notes as Coaching Error. | AC59: Manual at Structure (BE — premature per methodology, coaching error)
A60: 46155 | B60: Wed | C60: 2 | D60: Experiment Day 13 | E60: QQQ | F60: 711C | G60: 46155 | H60: Long | I60: 0.38137731 | J60: 0.38429398 | K60: 4.2 | L60: 1.74 | M60: 1.44 | N60: 1.44 | O60: 1.44 | P60: 1 | Q60: -30 | R60: 1.6 | S60: -31.6 | T60: 30 | U60: -1.05 | V60: A+ Bullish Slingshot (Scenario A: 1-min/2-min reset to floor + 5-min supportive) | W60: Hot PPI day — regime in question; bull continuation attempt after 711 break | X60: A (clean execution; setup matched criteria, market failed the move) | Y60: Yes (all) | Z60: No | AA60: 7 | AB60: Day 13 Trade 2. CLEAN PROCESS REP. After morning coaching errors and BE-flag on T1, reset emotionally (Mark Douglas "next trade" frame). 9:08 MT setup formed at 710.81: 1-min yellow 0, 2-min yellow 0, 5-min yellow 86 supportive — textbook Scenario A bullish slingshot after pullback to EMA cluster post-711 breakout. Coach called direct execute (corrected hedging from morning). Verbal verification completed: QQQ / 0DTE / 1 call / 30c stop. Entry 1.74 at 9:09:11. Peak open +$2 at 9:09. Pulled back to drawdown -$12 at 9:12 (price 710.68). HELD STRUCTURAL STOP — did NOT move to BE this time (lesson from T1 applied). Stop hit at 1.44 (30c premium loss) at 9:13:23 when price broke 710.30 structural support. Exit Method: Stop Hit = IDEAL methodology classification even on a loss. This is the disciplined trader's loss — sometimes A+ setups fail. Day 13 net: -$31.20. Daily stop -$75 not hit. Process discipline intact under post-coaching-error pressure. | AC60: Stop Hit

Sheet Rules
A1: 20-DAY EXPERIMENT — RULES OF ENGAGEMENT
A2: Start Date: 4/27/2026 | End Date: ~5/22/2026 (20 trading days)
A5: CORE RULES
A6: 1 | B6: A+ Long setups ONLY — Strong Trend conditions on 15-min
A7: 2 | B7: ZERO bear trades — bear win rate is 23.1%, off-limits for 20 days
A8: 3 | B8: Skip all B-grade and chop setups — discipline over action
A9: 4 | B9: 30-cent contract premium stop — NO EXCEPTIONS
A10: 5 | B10: No trades in first 15 minutes of RTH (7:30-7:45 MT)
A11: 6 | B11: Maximum 2 trades per day
A12: 7 | B12: Daily stop: -$75 (2 stopped trades = done)
A13: 8 | B13: After loss on same setup, skip identical setup for 30 minutes
A14: 9 | B14: 1 contract only — prove process before sizing up
A16: ENTRY TRIGGER (A+ SETUP)
A17: • | B17: 15-min macro: Strong Trend (price > red 200 MA, stoch crossing up from oversold)
A18: • | B18: Price at clear support (MA cluster, prior flush low, breakout retest)
A19: • | B19: 1-min stoch yellow at 0 (or near 0), curling up off the bottom
A20: • | B20: Enter on the CURL, BEFORE yellow crosses white (anticipation entry)
A21: • | B21: 2-min stoch supportive (oversold or rolling up)
A22: • | B22: 5-min stoch climbing (not rolling down)
A23: • | B23: Clean risk point within 30 cents premium / 1.5 points underlying
A25: MANAGEMENT RULES
A26: • | B26: Move stop to breakeven at +20 cents premium
A27: • | B27: DO NOT exit at +30 cents (historical leak — wins capped at $25-43)
A28: • | B28: Hold for +60 cents minimum unless setup invalidates
A29: • | B29: Setup invalidation = exit immediately (5-min stoch cross down, etc.)
A31: TRIGGERS TO BREAK RULES (KNOWN WEAKNESSES)
A32: • | B32: Fear — closing winners too early to lock in profit
A33: • | B33: FOMO — chasing setups that already moved
A34: • | B34: Revenge — trading after losses to "make it back"
A35: • | B35: Boredom — trading because nothing is happening
A37: IF I FEEL THESE, I:
A38: • | B38: Take a 10-minute break, walk away from the screen
A39: • | B39: Re-read the rules out loud
A40: • | B40: Check current mental state (1-10 scale)
A41: • | B41: If <7, do not trade
A43: END-OF-DAY PROCESS
A44: • | B44: Send TradeStation broker export to Claude
A45: • | B45: Send daily context note (setup, grade, condition, mental state, notes)
A46: • | B46: Claude updates master tracker
A48: END OF EXPERIMENT (20 days)
...

Sheet Daily Notes
A1: Date | B1: Day # | C1: Trades Taken | D1: P/L | E1: Mental State | F1: Rules Followed | G1: Key Observations | H1: Lessons / Pattern Notes
A2: 2026-04-27 | B2: Day 1 | C2: 1 | D2: -29.6 | E2: 8 | F2: All | G2: First trade of experiment. Entered $1.32 on pullback long, stopped at $1.04 (~$1.02 stop). Setup graded B+ in retrospect — entry was late, after deeper flush rather than at low. Held stop discipline through -$22 drawdown. Walked away after stop, applied cool-down rule. Watched 660.50->663.70 bounce without entering. Skipped multiple B+ setups during chop. Closed platform without forcing trade #2. | H2: KEY LESSON: Entry timing is the leak. Should have entered at the deeper flush low (660.50), not the bounce retest. Real-time screenshot/wait/analysis loop with Claude was costing 15-20 minutes — making setups stale. NEW PROCESS: morning prep, then I execute, send data after.
A3: 2026-04-28 | B3: Day 2 | C3: 1 | D3: 76.4 | E3: 9 | F3: All | G3: Pre-market gap-down recovery setup identified. Waited through 15-min rule. Watched first bounce 656->659 without chasing. Identified pullback box at 657.01-657.51. Entered $2.11 on the curl from 1-min stoch oversold. Initial $1.91 stop (20-cent risk). HELD past historical exit zone — let winner run. Exited $2.89 = +$76.40 = 3.82R. Best single trade ever recorded by $33. | H3: BREAKTHROUGH: First time letting winner run past +$30 leak. 9-min trade, 78-cent premium move. This is what the edge looks like when executed cleanly. Pre-market prep + fast execution + no real-time validation loop = the working process.
A4: 2026-04-29 | B4: Day 3 | C4: 0 | D4: 0 | E4: 9 | F4: All | G4: Fed Day (FOMC rate decision + Powell press conf at 12:00/12:30 MT). Made decision pre-open to be SIM-only. Took 1 SIM trade in morning that won (+$31 in SIM). Validated that A+ setup still fires in pre-Fed regime, but with smaller magnitude than yesterday's live winner. Did NOT go live despite winning SIM trade. Resisted the "would have been money" temptation. Continued SIM-only for rest of session. | H4: BREAKTHROUGH: Discipline tested in a different way today. Yesterday tested "walk away after winning live trade." Today tested "do not break the plan after winning SIM trade." Both passed. The fact that the SIM trade worked is randomness — the Fed day rule exists because variance is wider both directions, not because every Fed day is unprofitable. Sticking to the plan when a "would-have-been" winner appears is critical for long-term consistency.
A5: 2026-04-30 | B5: Day 4 | C5: 1 | D5: -34 | E5: 7 | F5: All | G5: Post-Fed regime. Pre-market gap up to 666 then violent rejection back to 661. Took A+ long setup at red 200 MA support at 7:46 MT. Setup criteria met (1-min curl, support, oversold). However regime had shifted to corrective - bullish thesis failed. Stopped at -$34. Did NOT take second trade despite eligibility - recognized regime mismatch. Observed clean A+ BEAR setup at 8:07 MT during cool-down (would have been +$108 hypothetical). Initiated bearish paper-trade research as direct response. | H5: CRITICAL INSIGHT: Bullish edge depends on regime. Day 2 winner came in Strong Trend recovery. Day 4 loss came in failed-bounce/consolidation regime. Same setup criteria, very different outcomes. Started paper-trading bearish A+ setups (mirror of bullish criteria) to build research dataset. Goal: have validated bearish edge data ready by Day 20 for potential Phase 2 introduction. Daily chart analysis revealed potential bearish divergence forming - regime may be shifting to corrective phase. Pattern recognition for regime change is the next skill to develop.
A6: 46143 | B6: 5 | C6: 1 | D6: 60.4 | E6: 9 | F6: Yes | G6: Gap up post-Day 4. ISM 8:00 MT: PMI 52.7 (miss), Employment 46.4 (miss/contractionary), New Orders 54.1 (beat), Prices 84.6 (hot - stagflation print). Market shrugged, rallied 3 pts to 676. Waited 65 min through extended OB. Pullback 8:30-8:37 to 5-min 9 EMA ~672, 1-min stoch reset to 0 + curl. Entered on curl. Held through give-back +25 to +10, second curl to +53, 4 rejections at 674. Exited 673.95 / $1.97 at end of mental capacity. Did not take 2nd trade. | H6: Best disciplined trade of experiment. Entered on curl not cross - primary historical leak FIXED. Held above $43 ceiling. Trailed stop through structural inflections. Exited at structural resistance, not random P/L. Stop management confirmed compliant - hardcoded 30c on entry, manually trailed BE -> +$45 -> +$50 -> +$15 lock as structure evolved. (Day 8 follow-up resolved earlier ambiguity.)
A7: 46146 | B7: 6 | C7: 0 | D7: 0 | E7: 7 | F7: Yes | G7: Range-bound chop 674-676 through pre-market and session. Pre-open framework correctly identified Path C (range chop). 4 rejections at 676, one failed breakout at 8:53. No A+ pullback to real support - 5-min 21 EMA at 674.75 never tested post-open. Closed platform 9:08 MT. Mid-day flush to 669 confirmed regime instability post-close. | H7: Discipline day. Staying flat in range chop = correct. No setup forced.
A8: 46147 | B8: 7 | C8: 0 | D8: 0 | E8: 8 | F8: Yes | G8: Overnight rally after Day 6 late flush. QQQ gap to 678+. ISM Services 53.6 (slight miss, decelerating), JOLTs 6.866M (in-line), New Home Sales 682K (beat), ISM Services Employment 45.2 (still contractionary). Net mildly dovish, soft-landing. Print spike 678 to 684 in 15 min, sharp reversal to 679 by 8:15. Three B+ pullback setups skipped: 8:20 (1-min curl at 1-min 21 EMA 679.66, single timeframe - ran 1.7 pts), 8:40 (1-min reset at 1-min 9 EMA 680.50, same), 8:54 (sideways base 680, multi-tf reset via time but no flush to real support). Closed platform ~9:28 MT. | H8: A+ requires multi-tf stoch alignment AND price at REAL support (5-min 21 EMA, 15-min 9 EMA, or major horizontal). Today pullbacks were micro to 1-min EMAs only - wrong location. Two consecutive days (Day 6, Day 7) of B+ setups without A+ alignment - track regime-specific (gap/news days) vs broader pattern. Day 20 evaluation: does B+ tier deserve its own framework with adjusted sizing/stops?
A9: 46148 | B9: 8 | C9: 1 | D9: -31.6 | E9: 8 | F9: Yes | G9: Massive overnight rally to 696, consolidating at 688 by pre-open. 15-min stoch finally showed real reset (slow 23, fast 0) - first multi-tf reset in over a week. 8:03 MT: QQQ pullback to 688 with 1-min/2-min reset, 5-min at 89 (elevated). Met WRITTEN A+ criteria but coach applied stricter 5-min reset interpretation. Skipped. Move ran ~$2 (would have been $80-100). 8:13: HOD, all tf extended - late entry, skipped (correct). 8:55: AAPL setup taken (1-min curl at 5-min 9 EMA support). Entry $2.40, hardcoded SBA stop. 9:08: invalidated, stop hit $2.10. Net -$31.60. | H9: Ticker discipline matters for experiment integrity. AAPL premium dynamics (gamma/IV/theta) differ from QQQ - cross-ticker data corrupts dataset. QQQ-only locked in. Hardcoded stop discipline confirmed working - should be default for all future trades. Rule clarification needed at Day 20: 5-min stoch climbing - fresh reset from <30 vs trend-aligned not-rolling? Today 8:03 setup highlighted ambiguity. Loss handled cleanly, no revenge trade considered.
A10: 46149 | B10: 9 | C10: 1 | D10: 165.4 | E10: 9 | F10: Yes (Contract expiry deviation - accidental) | G10: Steady overnight grind 691->696 pre-open. 15-min stoch finally showed clean fast-line reset. Pre-open framework correctly identified A+ environment. Multi-tf alignment achieved 7:48 at 695.93 (1-min curl + 2-min flush + 5-min fast at floor). Hardcoded SBA stop within 12 sec. Trailed structurally through BE -> +25 -> +40 -> +60 -> +80 -> +100. Held through give-backs. Manual market exit 8:15:57 at 5.43 on structural rejection of 699. R-multiple 5.51. Best disciplined trade of experiment by $89. | H10: BREAKTHROUGH: Multi-tf alignment is the differentiator. CONFIRMS looser interpretation of "5-min climbing" - trend-aligned with fast reset is sufficient. SKILL UPGRADE: Trailing structure beats trailing dollars. SKILL UPGRADE: Manual exit at structural rejection > stop-catch. WORKFLOW FIX REQUIRED: Selected 1DTE instead of 0DTE - accidental, not deliberate. Higher delta of 1DTE ITM strike captured ~$50 more than comparable 0DTE. ACTION: Implement pre-trade verbal verification (ticker/expiry/qty/stop) and set TradeStation default expiry filter to 0DTE.
A11: 46150 | B11: 10 | C11: 1 | D11: 89.4 | E11: 9 | F11: Yes | G11: NFP April 115K vs 62K consensus = strong beat. Pre-market gap from ~694 to 706+. Waited 1+ hour for real setup. Multi-tf alignment at 5-min EMA zone (~704-705). 1-min curl entry at 1.86. Hardcoded 30c initial stop, manually trailed structurally. Stop caught at 2.81 with 4c slippage (filled 2.77). FIRST clean execution of new structural-trail methodology. Held past every historical exit ($43, $57, $73, $102). Exit Method: Stop Hit (NOT manual at nerve). | H11: METHODOLOGY VALIDATION: New Structural Trail Stop rule executed cleanly. Stop caught the move on structural breakdown rather than manual exit at nerve. Slippage on SBA market stops is acceptable cost of discipline. Day 10 vs Day 9 comparison: Day 9 = manual exit (old method, bigger dollars), Day 10 = stop-hit (new method, smaller dollars but methodologically pure). Going forward, "Stop Hit" is the target outcome, not "Manual at Nerve". Pre-trade verification protocol worked - QQQ confirmed, 0DTE confirmed, 1 contract, 30c stop placed within 9 seconds.
A12: 46153 | B12: 11 | C12: 0 | D12: 0 | E12: 7 | F12: Yes | G12: Pre-CPI day. 15-min uptrend intact but tested — deepest pullback of move (709.78 low) held the 15-min 50 EMA. Two A+ identified: 7:42 in no-trade window (correctly skipped per rule), 8:32 at 15-min 50 EMA reset (skipped on over-strict 5-min "climbing" read — move ran +$3.56 underlying / est +$120-180 0DTE). Three B-grade attempts skipped (7:50, 7:58, 8:01). V-recovery to 712.50 supply correctly not chased. | H12: Checklist refinement (2nd occurrence, also flagged Day 8): 5-min "climbing" = "in position to climb" (yellow in support zone, ready to turn) when 15-min stoch is in fresh deep reset AND price at macro support. Bar-over-bar visible rise lags the 1-min curl trigger by definition — waiting for it = entering on confirmation = late. Apply Days 12-20. Two data points now (Day 8 + Day 11) where strict reading cost A+ quality setups by macro structure.
A13: 46154 | B13: Day 12 | C13: 0 | D13: 0 | E13: 8 | F13: Yes | G13: Hot CPI day (Core MoM 0.4% vs 0.3% cons; Core YoY 2.8% vs 2.7%; Headline YoY 3.8% vs 3.7%). Pre-market flush 712.79 → 706.82 (-0.91%). 15-min macro damaged — lower low confirmed, MAs flattening, Strong Trend Up tested. Per experiment rules (A+ longs require Strong Trend Up — broken) no live A+ available. Treated as paper-trade observation day. SIM bear practice session: SIM-1 -$8 (1-min curl trigger head-fake), SIM-2 +$217 (2-min curl trigger, structural trail, held through -$63 drawdown without panic). SIM session net +$208. Evening drive: discussed adding live shorts to experiment moving forward — confirmed by Aaron Day 13 morning. | H13: BREAKTHROUGH on bear side using own articulated 2-min curl methodology. Structural Trail Stop applies equally on bear side. Bear hypothesis: in violent bear regimes 2-min curl is the cleaner trigger than 1-min (which is too sensitive to countertrend pops). N=1 SIM validation — not yet a rule. Rule change captured Day 13 morning: live shorts added to experiment with same risk parameters as longs (1 contract, 30c stop, pre-trade verbal, daily stop -$75, max 2 trades/day combined). 15-min macro filter for shorts: "damaged/regime in question" sufficient (looser than strict mirror of Strong Trend Down). Tracker logging: same Trade Log rows, Direction column = "Short".
A14: 46155 | B14: Day 13 | C14: 2 | D14: -31.2 | E14: 7 | F14: Yes (all hard rules); coaching errors flagged on T1 BE move and missed morning A+ | G14: Hot PPI 6:30 MT: MoM 1.4% vs 0.5% cons (3x miss), Core MoM 1.0% vs 0.3% (3x miss), Core YoY 5.2% vs 4.3%, PPI YoY 6.0% vs 4.9%. Two consecutive hot inflation prints — disinflation narrative dead. Pre-open flush 712.79 → 706.32 then bounce. Morning A+ formed at 707.50-708 zone (multi-tf slingshot at held 706.32 macro support — Scenario A): MISSED due to coaching error (coach framed "falling knife" instead of "bullish slingshot at support" — anchored on PPI macro narrative). Move ran +$3+ / est +$100-130. Trade 1 (late entry 708.91): +$0.40 net after BE coaching error caught normal pullback (should have used structural trail at 708.45 per Day 10 methodology — would have captured +$70-90 more). Trade 2 (9:09 long, 711C): CLEAN PROCESS REP. Setup matched A+ criteria, executed properly, held structural stop (did NOT move to BE), Stop Hit at 30c. Day 13 net -$31.20. Daily stop -$75 not hit. | H14: TWO COACHING ERRORS FLAGGED — both mine: (1) Anchored on PPI macro narrative, missed the morning's A+ long setup by framing as "falling knife" / "your call" instead of direct execute call. The chart showed exact Scenario A bullish slingshot at held macro support. (2) Premature BE move on T1 — instructed BE at +$17 on a normal 30c pullback when structure had not broken. Per Day 10 Structural Trail Stop methodology, BE on first pullback is the historical leak — exit should be at structural break (708.45), not at BE. PROCESS CHANGE: When chart matches refined A+ criteria (Scenario A/B/C slingshot at structural support), coach gives DIRECT execute call. No more "your call" hedging on confirmed A+ setups. Macro narrative affects management margin (tighter trail, smaller cushion) — NOT entry decision. Structural Trail applies same on both directions. CRITICAL POSITIVE: Aaron handled coaching errors with grace (Mark Douglas "next trade" frame), reset emotionally, executed T2 cleanly with proper structural stop hold. T2 = ideal Stop Hit classification even on a loss. Discipline rep complete: held drawdown -$12 without moving to BE, structural stop did the work. Day 13 marks live shorts added to experiment (no short setup actually triggered today).

Sheet Bearish Paper
A1: BEARISH A+ SETUP — PAPER TRADE LOG (Research Phase)
A2: Tracking 'would-have-been' bear trades during the 20-day bullish-only experiment. NO live trades.
A4: Date | B4: Day | C4: Setup # | D4: Entry Time | E4: Exit Time | F4: Time in Trade (min) | G4: Underlying Entry | H4: Underlying Exit | I4: Strike | J4: Est. Premium Entry | K4: Est. Premium Exit | L4: Hypothetical P/L | M4: Setup Grade | N4: Notes
A5: 2026-04-30 | B5: Day 4 | C5: 1 | D5: 08:07 | E5: 08:22 | F5: 15 | G5: 661 | H5: 658.74 | I5: QQQ 660P | J5: 0.4 | K5: 1.5 | L5: 108.4 | M5: A | N5: TEXTBOOK A+ bearish setup formed during cool-down period after live bull trade stop-out. Major 666 daily rejection earlier, then bounce attempt failed at 661. 1-min stoch yellow at 100, curling down off top. 2-min stoch elevated, rolling. Mirror of bullish A+ setup (curl down at resistance vs curl up at support). Could not take live due to 30-min cool-down rule + no-bear-trades rule. Estimated +$108 hypothetical (~$1.10 premium expansion on 660P from $0.40 to $1.50 as underlying dropped 661→658.50).
A6: 46154 | B6: Day 12 | C6: 1 | D6: 08:14 | E6: ~08:25 | F6: 11 | G6: 708 | H6: 708.31 | I6: QQQ 708P (SIM) | J6: 1 | K6: 0.92 | L6: -8 | M6: B (early entry on 1-min head-fake curl) | N6: SIM trade — lesson rep. Entered put on 1-min "first hint of curl" (yellow 100→92) while white still climbing. Adverse move, exited at structure -$8 SIM. LESSON: yellow ticking down isn't a confirmed curl when white still climbing toward it. 1-min is head-fake prone in volatile bear regime. HYPOTHESIS FORMED: 2-min curl is the cleaner trigger for shorts in volatile bear regimes. Tested immediately on SIM-2.
A7: 46154 | B7: Day 12 | C7: 2 | D7: 08:56 | E7: ~09:30 (had to leave for work) | F7: 34 | G7: 705 | H7: 702 | I7: QQQ 705P (SIM) | J7: 1.5 | K7: 3.67 | L7: 217 | M7: A+ (Bear, Scenario A on 2-min curl) | N7: BREAKTHROUGH SIM TRADE. Entered on confirmed 2-min curl down at resistance after bounce. Held through -$63 drawdown (from +$125 to +$62) without panic-exit. Trailed structural stops: 704.55 → 703.70 → 703.55 → 702.60. 15-min red 200 EMA broke during the move. Closed +$217 when had to leave for work. Validates 2-min curl trigger hypothesis on volatile bear regime. Structural Trail Stop methodology applies same on bear side as bull side. SIM session net (SIM-1 + SIM-2) = +$208. Bear-side rep on historically-losing direction. Decision Day 13: live shorts added to experiment.
A8: BEARISH PAPER METRICS (Updates as you log more setups)
A9: Total Bear Setups Logged | B9: =COUNTA(A5:A50)-COUNTBLANK(A5:A50)
A10: Total Hypothetical P/L | B10: =SUM(L5:L50)
A11: Avg Hypothetical P/L per Setup | B11: =IFERROR(B10/B9,0)
A12: Hypothetical Wins (>$5) | B12: =COUNTIF(L5:L50,">5")
A13: Hypothetical Losses (<-$5) | B13: =COUNTIF(L5:L50,"<-5")
A14: Hypothetical Win Rate | B14: =IFERROR(B12/(B12+B13),0)
A17: A+ BEARISH SETUP CRITERIA (Mirror of Bullish A+)
A19: MACRO CONDITIONS (15-min)
A20: • | B20: Major rejection candle at resistance (e.g., gap-up rejected, ATH rejected)
A21: • | B21: 15-min stoch yellow rolling down from 100 (curling off top)
A22: • | B22: Price below recent swing high, attempting bounce that fails
A23: • | B23: Lower high forming after the rejection
A25: ENTRY TRIGGER (1-min) — MIRROR OF BULLISH
A26: • | B26: 1-min stoch yellow at 100 (or near 100)
A27: • | B27: Yellow curls DOWN off the top
A28: • | B28: Enter on the curl, BEFORE yellow crosses below white
A29: • | B29: 2-min stoch supportive (yellow elevated, rolling down)
A31: LOCATION REQUIREMENTS
A32: • | B32: Price at clear resistance (failed bounce from major rejection)
A33: • | B33: Bounce stalls at MA cluster, prior swing high, or 50% retrace of breakdown
A34: • | B34: Clean rejection candle structure on 1-min
A36: RISK MANAGEMENT
A37: • | B37: 30-cent premium stop (same rule as bulls)
A38: • | B38: Underlying stop: just above the bounce high
A39: • | B39: 1 contract only
A41: TARGETS
A42: • | B42: T1: Back to recent swing low
A43: • | B43: T2: Extension below swing low
A44: • | B44: Hold for $0.60+ premium move minimum
A46: INVALIDATION
A47: • | B47: 1-min yellow recrosses up through white = exit
A48: • | B48: Price reclaims the bounce high = setup failed
A49: • | B49: 5-min stoch yellow crosses up = trend reversing

Sheet B+ Skipped Setups
A1: B+ Skipped Setups - Discipline Log
A2: B+ tier setups correctly skipped per A+ filter. Hypothetical outcomes for Day 20 retrospective on filter calibration.
A3: Date | B3: Day | C3: Time (MT) | D3: Setup Description | E3: Skip Reason | F3: Hyp. Entry Premium | G3: Hypothetical Result
A4: 46147 | B4: 7 | C4: 0.34722222 | D4: 1-min stoch curl at 1-min 21 EMA (679.66) | E4: 5-min stoch not reset - single tf only | F4: 1.00 (est) | G4: Move ~$1.74 underlying / est. +$50-70
A5: 46147 | B5: 7 | C5: 0.36111111 | D5: 1-min reset at 1-min 9 EMA (680.50) | E5: Same - single tf only | F5: 1.05 (est) | G5: Setup chopped, marginal
A6: 46148 | B6: 8 | C6: 0.33541667 | D6: QQQ 1-min/2-min reset at 688 with 5-min stoch at 89 | E6: Coach applied stricter 5-min reset filter; setup met written criteria | G6: Move ~$2 underlying / est. +$80-100
A7: 46153 | B7: 11 | C7: 0.35555556 | D7: QQQ 1-min/2-min curl at 15-min 50 EMA (709.78) after deep flush — 15-min stoch reset to 9.36, multi-tf alignment | E7: Coach applied strict 5-min "climbing" filter (yellow at 0, white declining). Macro was A+ quality; checklist read was over-strict. | G7: Move ran 709.78 → 713.34 (+$3.56 underlying) in ~22 min. Est. +$120-180 on 0DTE near-ATM call with structural trail.
A8: 46155 | B8: 13 | C8: 07:50:00 | D8: QQQ 1-min/2-min curl from floor with 5-min in Scenario A slingshot (yellow at 0, white declining at 58) at held macro support 706.32 (post-PPI flush low). Multi-tf alignment forming for bullish slingshot off held 15-min red 200 area. | E8: COACHING ERROR — coach framed setup as "falling knife / continuation, not setup" at 7:46 and 7:49 due to anchoring on hot PPI bearish macro narrative. At 7:53 setup belatedly identified but framed as "your call" instead of direct execute. By 7:56 framed as "too late to enter." | F8: ~$1.85-2.00 (est for near-ATM 707C) | G8: Move ran 707.50 → 710.70 = +$3.20 underlying / est +$100-130 on 0DTE near-ATM call with structural trail. CRITICAL ENTRY: this is the entry Aaron marked with green arrows post-fact on his own chart at ~707.50-708 zone. Pattern recognition was Aaron's; coaching loop blocked execution.
